2020-02-20 12:26:55,791:app:Exception on /account/login [POST]
Traceback (most recent call last):
  File "C:\Users\lewis\PycharmProjects\The-Vertex\venv\lib\site-packages\flask\app.py", line 2446, in wsgi_app
    response = self.full_dispatch_request()
  File "C:\Users\lewis\PycharmProjects\The-Vertex\venv\lib\site-packages\flask\app.py", line 1951, in full_dispatch_request
    rv = self.handle_user_exception(e)
  File "C:\Users\lewis\PycharmProjects\The-Vertex\venv\lib\site-packages\flask\app.py", line 1820, in handle_user_exception
    reraise(exc_type, exc_value, tb)
  File "C:\Users\lewis\PycharmProjects\The-Vertex\venv\lib\site-packages\flask\_compat.py", line 39, in reraise
    raise value
  File "C:\Users\lewis\PycharmProjects\The-Vertex\venv\lib\site-packages\flask\app.py", line 1949, in full_dispatch_request
    rv = self.dispatch_request()
  File "C:\Users\lewis\PycharmProjects\The-Vertex\venv\lib\site-packages\flask\app.py", line 1935, in dispatch_request
    return self.view_functions[rule.endpoint](**req.view_args)
  File "C:\Users\lewis\PycharmProjects\The-Vertex\main\views\account_view.py", line 30, in login_post
    server_error = udf.check_if_input_error(password_first)  # Checks if password is valid
AttributeError: module 'main.data.transactions.user_db_transaction' has no attribute 'check_if_input_error'
2020-02-20 12:44:15,435:app:Exception on /account/login [POST]
Traceback (most recent call last):
  File "C:\Users\lewis\PycharmProjects\The-Vertex\venv\lib\site-packages\flask\app.py", line 2446, in wsgi_app
    response = self.full_dispatch_request()
  File "C:\Users\lewis\PycharmProjects\The-Vertex\venv\lib\site-packages\flask\app.py", line 1951, in full_dispatch_request
    rv = self.handle_user_exception(e)
  File "C:\Users\lewis\PycharmProjects\The-Vertex\venv\lib\site-packages\flask\app.py", line 1820, in handle_user_exception
    reraise(exc_type, exc_value, tb)
  File "C:\Users\lewis\PycharmProjects\The-Vertex\venv\lib\site-packages\flask\_compat.py", line 39, in reraise
    raise value
  File "C:\Users\lewis\PycharmProjects\The-Vertex\venv\lib\site-packages\flask\app.py", line 1949, in full_dispatch_request
    rv = self.dispatch_request()
  File "C:\Users\lewis\PycharmProjects\The-Vertex\venv\lib\site-packages\flask\app.py", line 1935, in dispatch_request
    return self.view_functions[rule.endpoint](**req.view_args)
  File "C:\Users\lewis\PycharmProjects\The-Vertex\main\views\account_view.py", line 42, in login_post
    if server_error:  # Returns login page if an error is found
UnboundLocalError: local variable 'server_error' referenced before assignment
2020-02-20 12:45:57,766:app:Exception on /account/register [POST]
Traceback (most recent call last):
  File "C:\Users\lewis\PycharmProjects\The-Vertex\venv\lib\site-packages\sqlalchemy\ext\declarative\clsregistry.py", line 294, in __call__
    x = eval(self.arg, globals(), self._dict)
  File "<string>", line 1, in <module>
NameError: name 'Subscription' is not defined

During handling of the above exception, another exception occurred:

Traceback (most recent call last):
  File "C:\Users\lewis\PycharmProjects\The-Vertex\venv\lib\site-packages\flask\app.py", line 2446, in wsgi_app
    response = self.full_dispatch_request()
  File "C:\Users\lewis\PycharmProjects\The-Vertex\venv\lib\site-packages\flask\app.py", line 1951, in full_dispatch_request
    rv = self.handle_user_exception(e)
  File "C:\Users\lewis\PycharmProjects\The-Vertex\venv\lib\site-packages\flask\app.py", line 1820, in handle_user_exception
    reraise(exc_type, exc_value, tb)
  File "C:\Users\lewis\PycharmProjects\The-Vertex\venv\lib\site-packages\flask\_compat.py", line 39, in reraise
    raise value
  File "C:\Users\lewis\PycharmProjects\The-Vertex\venv\lib\site-packages\flask\app.py", line 1949, in full_dispatch_request
    rv = self.dispatch_request()
  File "C:\Users\lewis\PycharmProjects\The-Vertex\venv\lib\site-packages\flask\app.py", line 1935, in dispatch_request
    return self.view_functions[rule.endpoint](**req.view_args)
  File "C:\Users\lewis\PycharmProjects\The-Vertex\main\views\account_view.py", line 125, in register_post
    elif udf.check_if_email_exists(email):  # Checks if email exists in database
  File "C:\Users\lewis\PycharmProjects\The-Vertex\main\data\transactions\user_db_transaction.py", line 162, in check_if_email_exists
    returned_user = session.query(User).filter(User.email == email).first()  # User of that email is searched
  File "C:\Users\lewis\PycharmProjects\The-Vertex\venv\lib\site-packages\sqlalchemy\orm\session.py", line 1553, in query
    return self._query_cls(entities, self, **kwargs)
  File "C:\Users\lewis\PycharmProjects\The-Vertex\venv\lib\site-packages\sqlalchemy\orm\query.py", line 191, in __init__
    self._set_entities(entities)
  File "C:\Users\lewis\PycharmProjects\The-Vertex\venv\lib\site-packages\sqlalchemy\orm\query.py", line 219, in _set_entities
    self._set_entity_selectables(self._entities)
  File "C:\Users\lewis\PycharmProjects\The-Vertex\venv\lib\site-packages\sqlalchemy\orm\query.py", line 250, in _set_entity_selectables
    ent.setup_entity(*d[entity])
  File "C:\Users\lewis\PycharmProjects\The-Vertex\venv\lib\site-packages\sqlalchemy\orm\query.py", line 4171, in setup_entity
    self._with_polymorphic = ext_info.with_polymorphic_mappers
  File "C:\Users\lewis\PycharmProjects\The-Vertex\venv\lib\site-packages\sqlalchemy\util\langhelpers.py", line 855, in __get__
    obj.__dict__[self.__name__] = result = self.fget(obj)
  File "C:\Users\lewis\PycharmProjects\The-Vertex\venv\lib\site-packages\sqlalchemy\orm\mapper.py", line 2135, in _with_polymorphic_mappers
    configure_mappers()
  File "C:\Users\lewis\PycharmProjects\The-Vertex\venv\lib\site-packages\sqlalchemy\orm\mapper.py", line 3249, in configure_mappers
    mapper._post_configure_properties()
  File "C:\Users\lewis\PycharmProjects\The-Vertex\venv\lib\site-packages\sqlalchemy\orm\mapper.py", line 1947, in _post_configure_properties
    prop.init()
  File "C:\Users\lewis\PycharmProjects\The-Vertex\venv\lib\site-packages\sqlalchemy\orm\interfaces.py", line 196, in init
    self.do_init()
  File "C:\Users\lewis\PycharmProjects\The-Vertex\venv\lib\site-packages\sqlalchemy\orm\relationships.py", line 1914, in do_init
    self._process_dependent_arguments()
  File "C:\Users\lewis\PycharmProjects\The-Vertex\venv\lib\site-packages\sqlalchemy\orm\relationships.py", line 1976, in _process_dependent_arguments
    self.target = self.entity.persist_selectable
  File "C:\Users\lewis\PycharmProjects\The-Vertex\venv\lib\site-packages\sqlalchemy\util\langhelpers.py", line 855, in __get__
    obj.__dict__[self.__name__] = result = self.fget(obj)
  File "C:\Users\lewis\PycharmProjects\The-Vertex\venv\lib\site-packages\sqlalchemy\orm\relationships.py", line 1881, in entity
    argument = self.argument()
  File "C:\Users\lewis\PycharmProjects\The-Vertex\venv\lib\site-packages\sqlalchemy\ext\declarative\clsregistry.py", line 306, in __call__
    % (self.prop.parent, self.arg, n.args[0], self.cls)
sqlalchemy.exc.InvalidRequestError: When initializing mapper mapped class ActivityType->ActivityTypes, expression 'Subscription' failed to locate a name ("name 'Subscription' is not defined"). If this is a class name, consider adding this relationship() to the <class 'main.data.db_classes.activity_db_class.ActivityType'> class after both dependent classes have been defined.
2020-02-20 12:46:46,359:app:Exception on /account/register [POST]
Traceback (most recent call last):
  File "C:\Users\lewis\PycharmProjects\The-Vertex\venv\lib\site-packages\flask\app.py", line 2446, in wsgi_app
    response = self.full_dispatch_request()
  File "C:\Users\lewis\PycharmProjects\The-Vertex\venv\lib\site-packages\flask\app.py", line 1951, in full_dispatch_request
    rv = self.handle_user_exception(e)
  File "C:\Users\lewis\PycharmProjects\The-Vertex\venv\lib\site-packages\flask\app.py", line 1820, in handle_user_exception
    reraise(exc_type, exc_value, tb)
  File "C:\Users\lewis\PycharmProjects\The-Vertex\venv\lib\site-packages\flask\_compat.py", line 39, in reraise
    raise value
  File "C:\Users\lewis\PycharmProjects\The-Vertex\venv\lib\site-packages\flask\app.py", line 1949, in full_dispatch_request
    rv = self.dispatch_request()
  File "C:\Users\lewis\PycharmProjects\The-Vertex\venv\lib\site-packages\flask\app.py", line 1935, in dispatch_request
    return self.view_functions[rule.endpoint](**req.view_args)
  File "C:\Users\lewis\PycharmProjects\The-Vertex\main\views\account_view.py", line 136, in register_post
    if server_error: # If there was an error then the normal register page is loaded with all the values that the user
UnboundLocalError: local variable 'server_error' referenced before assignment
